#VRML_SIM R2022b utf8
# license: Apache License 2.0
# license url: http://www.apache.org/licenses/LICENSE-2.0
# This is a proto file for Webots for the RobotDescription
# Extracted from: /home/hp/robot_ws/src/robot_description/urdf/robot_description.urdf

PROTO RobotDescription [
  field  SFVec3f     translation     0 0 0
  field  SFRotation  rotation        0 0 1 0
  field  SFString    name            "RobotDescription"  # Is `Robot.name`.
  field  SFString    controller      "void"              # Is `Robot.controller`.
  field  MFString    controllerArgs  []                  # Is `Robot.controllerArgs`.
  field  SFString    customData      ""                  # Is `Robot.customData`.
  field  SFBool      supervisor      FALSE               # Is `Robot.supervisor`.
  field  SFBool      synchronization TRUE                # Is `Robot.synchronization`.
  field  SFBool      selfCollision   FALSE               # Is `Robot.selfCollision`.
]
{
  Robot {
    translation IS translation
    rotation IS rotation
    controller IS controller
    controllerArgs IS controllerArgs
    customData IS customData
    supervisor IS supervisor
    synchronization IS synchronization
    selfCollision IS selfCollision
    children [
      Shape {
        appearance DEF base_link_material PBRAppearance {
          roughness 1.000000
          metalness 0
        }
        geometry DEF base_link Mesh {
          url "/home/hp/robot_ws/src/robot_description/meshes/base_link.STL"
        }
      }
      HingeJoint {
        jointParameters HingeJointParameters {
          axis 0.000000 0.000000 1.000000
        }
        device [
          RotationalMotor {
            name "joint1"
            minPosition -1.5708
            maxPosition 1.5708
            maxTorque 10000
          }
          PositionSensor {
            name "joint1_sensor"
          }
        ]
        endPoint Solid {
          children [
            Shape {
              appearance DEF link1_material PBRAppearance {
                baseColor 0.690200 0.690200 0.690200
                roughness 1.000000
                metalness 0
              }
              geometry DEF link1 Mesh {
                url "/home/hp/robot_ws/src/robot_description/meshes/link1.STL"
              }
            }
            HingeJoint {
              jointParameters HingeJointParameters {
                axis 0.000000 1.000000 -0.000004
                anchor 0.000000 0.000000 -0.090000
              }
              device [
                RotationalMotor {
                  name "joint2"
                  minPosition -1.5708
                  maxPosition 1.5708
                  maxTorque 10000
                }
                PositionSensor {
                  name "joint2_sensor"
                }
              ]
              endPoint Solid {
                translation 0.000000 0.000000 -0.090000
                rotation -1.000000 0.000000 0.000000 1.570800
                children [
                  Shape {
                    appearance DEF link2_material PBRAppearance {
                      baseColor 0.898040 0.921570 0.929410
                      roughness 1.000000
                      metalness 0
                    }
                    geometry DEF link2 Mesh {
                      url "/home/hp/robot_ws/src/robot_description/meshes/link2.STL"
                    }
                  }
                  HingeJoint {
                    jointParameters HingeJointParameters {
                      axis 0.000000 1.000000 -0.000004
                    }
                    device [
                      RotationalMotor {
                        name "joint3"
                        minPosition -1.5708
                        maxPosition 1.5708
                        maxTorque 10000
                      }
                      PositionSensor {
                        name "joint3_sensor"
                      }
                    ]
                    endPoint Solid {
                      rotation -1.000000 0.000000 0.000000 1.570800
                      children [
                        Shape {
                          appearance DEF link3_material PBRAppearance {
                            baseColor 0.898040 0.921570 0.929410
                            roughness 1.000000
                            metalness 0
                          }
                          geometry DEF link3 Mesh {
                            url "/home/hp/robot_ws/src/robot_description/meshes/link3.STL"
                          }
                        }
                        HingeJoint {
                          jointParameters HingeJointParameters {
                            axis 0.000000 -1.000000 -0.000004
                            anchor 0.000000 0.000000 0.247000
                          }
                          device [
                            RotationalMotor {
                              name "joint4"
                              minPosition -1.5708
                              maxPosition 1.5708
                              maxTorque 10000
                            }
                            PositionSensor {
                              name "joint4_sensor"
                            }
                          ]
                          endPoint Solid {
                            translation 0.000000 0.000000 0.247000
                            rotation 1.000000 0.000000 0.000000 1.570800
                            children [
                              Shape {
                                appearance DEF link4_material PBRAppearance {
                                  baseColor 0.898040 0.917650 0.929410
                                  roughness 1.000000
                                  metalness 0
                                }
                                geometry DEF link4 Mesh {
                                  url "/home/hp/robot_ws/src/robot_description/meshes/link4.STL"
                                }
                              }
                              HingeJoint {
                                jointParameters HingeJointParameters {
                                  axis 0.000000 1.000000 -0.000004
                                }
                                device [
                                  RotationalMotor {
                                    name "joint5"
                                    minPosition -1.5708
                                    maxPosition 1.5708
                                    maxTorque 10000
                                  }
                                  PositionSensor {
                                    name "joint5_sensor"
                                  }
                                ]
                                endPoint Solid {
                                  rotation -1.000000 0.000000 0.000000 1.570800
                                  children [
                                    Shape {
                                      appearance DEF link5_material PBRAppearance {
                                        baseColor 0.898040 0.921570 0.929410
                                        roughness 1.000000
                                        metalness 0
                                      }
                                      geometry DEF link5 Mesh {
                                        url "/home/hp/robot_ws/src/robot_description/meshes/link5.STL"
                                      }
                                    }
                                    HingeJoint {
                                      jointParameters HingeJointParameters {
                                        axis 0.000000 -1.000000 -0.000004
                                        anchor 0.000000 0.000000 0.210500
                                      }
                                      device [
                                        RotationalMotor {
                                          name "joint6"
                                          minPosition -1.5708
                                          maxPosition 1.5708
                                          maxTorque 10000
                                        }
                                        PositionSensor {
                                          name "joint6_sensor"
                                        }
                                      ]
                                      endPoint Solid {
                                        translation 0.000000 0.000000 0.210500
                                        rotation 1.000000 0.000000 0.000000 1.570800
                                        children [
                                          Shape {
                                            appearance DEF link6_material PBRAppearance {
                                              baseColor 0.898040 0.917650 0.929410
                                              roughness 1.000000
                                              metalness 0
                                            }
                                            geometry DEF link6 Mesh {
                                              url "/home/hp/robot_ws/src/robot_description/meshes/link6.STL"
                                            }
                                          }
                                          HingeJoint {
                                            jointParameters HingeJointParameters {
                                              axis 0.000000 1.000000 -0.000004
                                            }
                                            device [
                                              RotationalMotor {
                                                name "joint7"
                                                minPosition -1.5708
                                                maxPosition 1.5708
                                                maxTorque 10000
                                              }
                                              PositionSensor {
                                                name "joint7_sensor"
                                              }
                                            ]
                                            endPoint Solid {
                                              rotation -1.000000 0.000000 0.000000 1.570800
                                              children [
                                                Shape {
                                                  appearance DEF link7_material PBRAppearance {
                                                    baseColor 0.752940 0.752940 0.752940
                                                    roughness 1.000000
                                                    metalness 0
                                                  }
                                                  geometry DEF link7 Mesh {
                                                    url "/home/hp/robot_ws/src/robot_description/meshes/link7.STL"
                                                  }
                                                }
                                              ]
                                              name "link7"
                                              boundingObject USE link7
                                              physics Physics {
                                                density -1
                                                mass 0.149290
                                                centerOfMass [ -0.000014 -0.000001 0.237360 ]
                                                inertiaMatrix [
                                                  7.637500e-05 7.256500e-05 4.075100e-05
                                                  -1.247500e-07 -3.364600e-09 8.014400e-10
                                                ]
                                              }
                                            }
                                          }
                                        ]
                                        name "link6"
                                        boundingObject USE link6
                                        physics Physics {
                                          density -1
                                          mass 0.159320
                                          centerOfMass [ -0.000003 0.055699 0.003099 ]
                                          inertiaMatrix [
                                            2.764400e-04 2.284900e-04 1.504800e-04
                                            2.211400e-07 -1.298300e-07 5.916300e-07
                                          ]
                                        }
                                      }
                                    }
                                  ]
                                  name "link5"
                                  boundingObject USE link5
                                  physics Physics {
                                    density -1
                                    mass 0.327900
                                    centerOfMass [ -0.000038 -0.004006 0.200190 ]
                                    inertiaMatrix [
                                      5.927100e-04 6.105700e-04 2.777600e-04
                                      -4.495900e-07 -8.426700e-07 9.230800e-06
                                    ]
                                  }
                                }
                              }
                            ]
                            name "link4"
                            boundingObject USE link4
                            physics Physics {
                              density -1
                              mass 0.368870
                              centerOfMass [ -0.000217 0.060002 0.003511 ]
                              inertiaMatrix [
                                1.041600e-03 8.039600e-04 5.537800e-04
                                6.470200e-07 1.318700e-06 2.428100e-05
                              ]
                            }
                          }
                        }
                      ]
                      name "link3"
                      boundingObject USE link3
                      physics Physics {
                        density -1
                        mass 0.377560
                        centerOfMass [ 0.000220 -0.006687 0.234420 ]
                        inertiaMatrix [
                          7.435300e-04 6.774700e-04 4.121300e-04
                          6.720900e-07 -1.039700e-06 4.177900e-06
                        ]
                      }
                    }
                  }
                ]
                name "link2"
                boundingObject USE link2
                physics Physics {
                  density -1
                  mass 0.861640
                  centerOfMass [ 0.000030 0.097541 0.000205 ]
                  inertiaMatrix [
                    3.276000e-03 1.677900e-03 2.194600e-03
                    1.059600e-06 -3.071900e-07 1.646000e-05
                  ]
                }
              }
            }
          ]
          name "link1"
          boundingObject USE link1
          physics Physics {
            density -1
            mass 0.641880
            centerOfMass [ -0.000126 0.005309 -0.071768 ]
            inertiaMatrix [
              1.766200e-03 1.600500e-03 1.099500e-03
              4.546900e-07 -3.047500e-06 2.606400e-06
            ]
          }
        }
      }
    ]
    name IS name
    boundingObject Transform {
            translation 0 0 -1.3
            rotation 0 0 0 0
            children [
              Box {
                size 1.3 1.3 0.2
              }
            ]
                         }
    physics Physics {
      density -1
      mass 18.864000
      centerOfMass [ -0.000001 0.005622 -0.338800 ]
      inertiaMatrix [
        7.092800e+00 8.704100e+00 9.474800e+00
        -1.851400e-07 9.165100e-07 -4.241700e-03
      ]
    }
  }
}
